Workbook

Sheet Summary
B2: Building | C2: Floor | D2: Area | E2: Allocated | F2: HW | G2: Available | H2: Total Desks with/ HW | J2: Building | K2: Floor | L2: Allocated | M2: HW | N2: Available | O2: Total Desks - w/o HW | P2: Total Desks - with/ HW
B3: T | C3: 3 | D3: A | E3: =COUNTIFS(Tower_3!$J:$J,Summary!$E$2,Tower_3!$B:$B,Summary!$C3,Tower_3!$C:$C,Summary!$D3) | F3: =COUNTIFS(Tower_3!$J:$J,Summary!$F$2,Tower_3!$B:$B,Summary!$C3,Tower_3!$C:$C,Summary!$D3) | G3: =COUNTIFS(Tower_3!$J:$J,Summary!$G$2,Tower_3!$B:$B,Summary!$C3,Tower_3!$C:$C,Summary!$D3) | H3: =SUM(E3:G3) | J3: T | K3: 3 | L3: =SUMIFS(E:E,$B:$B,$J3,$C:$C,$K3) | M3: =SUMIFS(F:F,$B:$B,$J3,$C:$C,$K3) | N3: =SUMIFS(G:G,$B:$B,$J3,$C:$C,$K3) | O3: =L3+N3 | P3: =SUM(L3:N3)
B4: T | C4: 3 | D4: B | E4: =COUNTIFS(Tower_3!$J:$J,Summary!$E$2,Tower_3!$B:$B,Summary!$C4,Tower_3!$C:$C,Summary!$D4) | F4: =COUNTIFS(Tower_3!$J:$J,Summary!$F$2,Tower_3!$B:$B,Summary!$C4,Tower_3!$C:$C,Summary!$D4) | G4: =COUNTIFS(Tower_3!$J:$J,Summary!$G$2,Tower_3!$B:$B,Summary!$C4,Tower_3!$C:$C,Summary!$D4) | H4: =SUM(E4:G4) | J4: T | K4: 4 | L4: =SUMIFS(E:E,$B:$B,$J4,$C:$C,$K4) | M4: =SUMIFS(F:F,$B:$B,$J4,$C:$C,$K4) | N4: =SUMIFS(G:G,$B:$B,$J4,$C:$C,$K4) | O4: =L4+N4 | P4: =SUM(L4:N4)
B5: T | C5: 3 | D5: C | E5: =COUNTIFS(Tower_3!$J:$J,Summary!$E$2,Tower_3!$B:$B,Summary!$C5,Tower_3!$C:$C,Summary!$D5) | F5: =COUNTIFS(Tower_3!$J:$J,Summary!$F$2,Tower_3!$B:$B,Summary!$C5,Tower_3!$C:$C,Summary!$D5) | G5: =COUNTIFS(Tower_3!$J:$J,Summary!$G$2,Tower_3!$B:$B,Summary!$C5,Tower_3!$C:$C,Summary!$D5) | H5: =SUM(E5:G5) | J5: T | K5: 5 | L5: =SUMIFS(E:E,$B:$B,$J5,$C:$C,$K5) | M5: =SUMIFS(F:F,$B:$B,$J5,$C:$C,$K5) | N5: =SUMIFS(G:G,$B:$B,$J5,$C:$C,$K5) | O5: =L5+N5 | P5: =SUM(L5:N5)
B6: T | C6: 3 | D6: D | E6: =COUNTIFS(Tower_3!$J:$J,Summary!$E$2,Tower_3!$B:$B,Summary!$C6,Tower_3!$C:$C,Summary!$D6) | F6: =COUNTIFS(Tower_3!$J:$J,Summary!$F$2,Tower_3!$B:$B,Summary!$C6,Tower_3!$C:$C,Summary!$D6) | G6: =COUNTIFS(Tower_3!$J:$J,Summary!$G$2,Tower_3!$B:$B,Summary!$C6,Tower_3!$C:$C,Summary!$D6) | H6: =SUM(E6:G6) | J6: T | K6: 6 | L6: =SUMIFS(E:E,$B:$B,$J6,$C:$C,$K6) | M6: =SUMIFS(F:F,$B:$B,$J6,$C:$C,$K6) | N6: =SUMIFS(G:G,$B:$B,$J6,$C:$C,$K6) | O6: =L6+N6 | P6: =SUM(L6:N6)
B7: T | C7: 4 | D7: A | E7: =COUNTIFS(Tower_4!$J:$J,Summary!$E$2,Tower_4!$B:$B,Summary!$C7,Tower_4!$C:$C,Summary!$D7) | F7: =COUNTIFS(Tower_4!$J:$J,Summary!$F$2,Tower_4!$B:$B,Summary!$C7,Tower_4!$C:$C,Summary!$D7) | G7: =COUNTIFS(Tower_4!$J:$J,Summary!$G$2,Tower_4!$B:$B,Summary!$C7,Tower_4!$C:$C,Summary!$D7) | H7: =SUM(E7:G7) | J7: R | K7: 3 | L7: =SUMIFS(E:E,$B:$B,$J7,$C:$C,$K7) | M7: =SUMIFS(F:F,$B:$B,$J7,$C:$C,$K7) | N7: =SUMIFS(G:G,$B:$B,$J7,$C:$C,$K7) | O7: =L7+N7 | P7: =SUM(L7:N7)
B8: T | C8: 4 | D8: B | E8: =COUNTIFS(Tower_4!$J:$J,Summary!$E$2,Tower_4!$B:$B,Summary!$C8,Tower_4!$C:$C,Summary!$D8) | F8: =COUNTIFS(Tower_4!$J:$J,Summary!$F$2,Tower_4!$B:$B,Summary!$C8,Tower_4!$C:$C,Summary!$D8) | G8: =COUNTIFS(Tower_3!$J:$J,Summary!$G$2,Tower_3!$B:$B,Summary!$C8,Tower_3!$C:$C,Summary!$D8) | H8: =SUM(E8:G8) | J8: R | K8: 4 | L8: =SUMIFS(E:E,$B:$B,$J8,$C:$C,$K8) | M8: =SUMIFS(F:F,$B:$B,$J8,$C:$C,$K8) | N8: =SUMIFS(G:G,$B:$B,$J8,$C:$C,$K8) | O8: =L8+N8 | P8: =SUM(L8:N8)
B9: T | C9: 4 | D9: C | E9: =COUNTIFS(Tower_4!$J:$J,Summary!$E$2,Tower_4!$B:$B,Summary!$C9,Tower_4!$C:$C,Summary!$D9) | F9: =COUNTIFS(Tower_4!$J:$J,Summary!$F$2,Tower_4!$B:$B,Summary!$C9,Tower_4!$C:$C,Summary!$D9) | G9: =COUNTIFS(Tower_3!$J:$J,Summary!$G$2,Tower_3!$B:$B,Summary!$C9,Tower_3!$C:$C,Summary!$D9) | H9: =SUM(E9:G9) | J9: R | K9: 5 | L9: =SUMIFS(E:E,$B:$B,$J9,$C:$C,$K9) | M9: =SUMIFS(F:F,$B:$B,$J9,$C:$C,$K9) | N9: =SUMIFS(G:G,$B:$B,$J9,$C:$C,$K9) | O9: =L9+N9 | P9: =SUM(L9:N9)
B10: T | C10: 4 | D10: D | E10: =COUNTIFS(Tower_4!$J:$J,Summary!$E$2,Tower_4!$B:$B,Summary!$C10,Tower_4!$C:$C,Summary!$D10) | F10: =COUNTIFS(Tower_4!$J:$J,Summary!$F$2,Tower_4!$B:$B,Summary!$C10,Tower_4!$C:$C,Summary!$D10) | G10: =COUNTIFS(Tower_3!$J:$J,Summary!$G$2,Tower_3!$B:$B,Summary!$C10,Tower_3!$C:$C,Summary!$D10) | H10: =SUM(E10:G10) | K10: TOTAL | L10: =SUM(L3:L9) | M10: =SUM(M3:M9) | N10: =SUM(N3:N9) | O10: =SUM(O3:O9) | P10: =SUM(L10:N10)
B11: T | C11: 5 | D11: A | E11: =COUNTIFS(Tower_5!$J:$J,Summary!$E$2,Tower_5!$B:$B,Summary!$C11,Tower_5!$C:$C,Summary!$D11) | F11: =COUNTIFS(Tower_5!$J:$J,Summary!$F$2,Tower_5!$B:$B,Summary!$C11,Tower_5!$C:$C,Summary!$D11) | G11: =COUNTIFS(Tower_5!$J:$J,Summary!$G$2,Tower_5!$B:$B,Summary!$C11,Tower_5!$C:$C,Summary!$D11) | H11: =SUM(E11:G11)
B12: T | C12: 5 | D12: B | E12: =COUNTIFS(Tower_5!$J:$J,Summary!$E$2,Tower_5!$B:$B,Summary!$C12,Tower_5!$C:$C,Summary!$D12) | F12: =COUNTIFS(Tower_5!$J:$J,Summary!$F$2,Tower_5!$B:$B,Summary!$C12,Tower_5!$C:$C,Summary!$D12) | G12: =COUNTIFS(Tower_5!$J:$J,Summary!$G$2,Tower_5!$B:$B,Summary!$C12,Tower_5!$C:$C,Summary!$D12) | H12: =SUM(E12:G12) | K12: Total Tower | L12: =SUM(L3:L6) | M12: =SUM(M3:M6) | N12: =SUM(N3:N6) | O12: =SUM(O3:O6) | P12: =SUM(P3:P6)
B13: T | C13: 5 | D13: C | E13: =COUNTIFS(Tower_5!$J:$J,Summary!$E$2,Tower_5!$B:$B,Summary!$C13,Tower_5!$C:$C,Summary!$D13) | F13: =COUNTIFS(Tower_5!$J:$J,Summary!$F$2,Tower_5!$B:$B,Summary!$C13,Tower_5!$C:$C,Summary!$D13) | G13: =COUNTIFS(Tower_5!$J:$J,Summary!$G$2,Tower_5!$B:$B,Summary!$C13,Tower_5!$C:$C,Summary!$D13) | H13: =SUM(E13:G13) | K13: Total Riviera | L13: =SUM(L7:L9) | M13: =SUM(M7:M9) | N13: =SUM(N7:N9) | O13: =SUM(O7:O9) | P13: =SUM(P7:P9)
B14: T | C14: 5 | D14: D | E14: =COUNTIFS(Tower_5!$J:$J,Summary!$E$2,Tower_5!$B:$B,Summary!$C14,Tower_5!$C:$C,Summary!$D14) | F14: =COUNTIFS(Tower_5!$J:$J,Summary!$F$2,Tower_5!$B:$B,Summary!$C14,Tower_5!$C:$C,Summary!$D14) | G14: =COUNTIFS(Tower_5!$J:$J,Summary!$G$2,Tower_5!$B:$B,Summary!$C14,Tower_5!$C:$C,Summary!$D14) | H14: =SUM(E14:G14)
B15: T | C15: 6 | D15: A | E15: =COUNTIFS(Tower_6!$J:$J,Summary!$E$2,Tower_6!$B:$B,Summary!$C15,Tower_6!$C:$C,Summary!$D15) | F15: =COUNTIFS(Tower_6!$J:$J,Summary!$F$2,Tower_6!$B:$B,Summary!$C15,Tower_6!$C:$C,Summary!$D15) | G15: =COUNTIFS(Tower_6!$J:$J,Summary!$G$2,Tower_6!$B:$B,Summary!$C15,Tower_6!$C:$C,Summary!$D15) | H15: =SUM(E15:G15)
B16: T | C16: 6 | D16: B | E16: =COUNTIFS(Tower_6!$J:$J,Summary!$E$2,Tower_6!$B:$B,Summary!$C16,Tower_6!$C:$C,Summary!$D16) | F16: =COUNTIFS(Tower_6!$J:$J,Summary!$F$2,Tower_6!$B:$B,Summary!$C16,Tower_6!$C:$C,Summary!$D16) | G16: =COUNTIFS(Tower_6!$J:$J,Summary!$G$2,Tower_6!$B:$B,Summary!$C16,Tower_6!$C:$C,Summary!$D16) | H16: =SUM(E16:G16)
B17: T | C17: 6 | D17: C | E17: =COUNTIFS(Tower_6!$J:$J,Summary!$E$2,Tower_6!$B:$B,Summary!$C17,Tower_6!$C:$C,Summary!$D17) | F17: =COUNTIFS(Tower_6!$J:$J,Summary!$F$2,Tower_6!$B:$B,Summary!$C17,Tower_6!$C:$C,Summary!$D17) | G17: =COUNTIFS(Tower_6!$J:$J,Summary!$G$2,Tower_6!$B:$B,Summary!$C17,Tower_6!$C:$C,Summary!$D17) | H17: =SUM(E17:G17)
B18: T | C18: 6 | D18: D | E18: =COUNTIFS(Tower_6!$J:$J,Summary!$E$2,Tower_6!$B:$B,Summary!$C18,Tower_6!$C:$C,Summary!$D18) | F18: =COUNTIFS(Tower_6!$J:$J,Summary!$F$2,Tower_6!$B:$B,Summary!$C18,Tower_6!$C:$C,Summary!$D18) | G18: =COUNTIFS(Tower_6!$J:$J,Summary!$G$2,Tower_6!$B:$B,Summary!$C18,Tower_6!$C:$C,Summary!$D18) | H18: =SUM(E18:G18)
B19: R | C19: 3 | D19: E | E19: =COUNTIFS(Riviera_3!$J:$J,Summary!$E$2,Riviera_3!$B:$B,Summary!$C19,Riviera_3!$C:$C,Summary!$D19) | F19: =COUNTIFS(Riviera_3!$J:$J,Summary!$F$2,Riviera_3!$B:$B,Summary!$C19,Riviera_3!$C:$C,Summary!$D19) | G19: =COUNTIFS(Riviera_3!$J:$J,Summary!$G$2,Riviera_3!$B:$B,Summary!$C19,Riviera_3!$C:$C,Summary!$D19) | H19: =SUM(E19:G19)
B20: R | C20: 3 | D20: F | E20: =COUNTIFS(Riviera_3!$J:$J,Summary!$E$2,Riviera_3!$B:$B,Summary!$C20,Riviera_3!$C:$C,Summary!$D20) | F20: =COUNTIFS(Riviera_3!$J:$J,Summary!$F$2,Riviera_3!$B:$B,Summary!$C20,Riviera_3!$C:$C,Summary!$D20) | G20: =COUNTIFS(Riviera_3!$J:$J,Summary!$G$2,Riviera_3!$B:$B,Summary!$C20,Riviera_3!$C:$C,Summary!$D20) | H20: =SUM(E20:G20)
B21: R | C21: 3 | D21: G | E21: =COUNTIFS(Riviera_3!$J:$J,Summary!$E$2,Riviera_3!$B:$B,Summary!$C21,Riviera_3!$C:$C,Summary!$D21) | F21: =COUNTIFS(Riviera_3!$J:$J,Summary!$F$2,Riviera_3!$B:$B,Summary!$C21,Riviera_3!$C:$C,Summary!$D21) | G21: =COUNTIFS(Riviera_3!$J:$J,Summary!$G$2,Riviera_3!$B:$B,Summary!$C21,Riviera_3!$C:$C,Summary!$D21) | H21: =SUM(E21:G21)
B22: R | C22: 3 | D22: H | E22: =COUNTIFS(Riviera_3!$J:$J,Summary!$E$2,Riviera_3!$B:$B,Summary!$C22,Riviera_3!$C:$C,Summary!$D22) | F22: =COUNTIFS(Riviera_3!$J:$J,Summary!$F$2,Riviera_3!$B:$B,Summary!$C22,Riviera_3!$C:$C,Summary!$D22) | G22: =COUNTIFS(Riviera_3!$J:$J,Summary!$G$2,Riviera_3!$B:$B,Summary!$C22,Riviera_3!$C:$C,Summary!$D22) | H22: =SUM(E22:G22)
B23: R | C23: 4 | D23: E | E23: =COUNTIFS(Riviera_4!$J:$J,Summary!$E$2,Riviera_4!$B:$B,Summary!$C23,Riviera_4!$C:$C,Summary!$D23) | F23: =COUNTIFS(Riviera_4!$J:$J,Summary!$F$2,Riviera_4!$B:$B,Summary!$C23,Riviera_4!$C:$C,Summary!$D23) | G23: =COUNTIFS(Riviera_4!$J:$J,Summary!$G$2,Riviera_4!$B:$B,Summary!$C23,Riviera_4!$C:$C,Summary!$D23) | H23: =SUM(E23:G23)
B24: R | C24: 4 | D24: F | E24: =COUNTIFS(Riviera_4!$J:$J,Summary!$E$2,Riviera_4!$B:$B,Summary!$C24,Riviera_4!$C:$C,Summary!$D24) | F24: =COUNTIFS(Riviera_4!$J:$J,Summary!$F$2,Riviera_4!$B:$B,Summary!$C24,Riviera_4!$C:$C,Summary!$D24) | G24: =COUNTIFS(Riviera_4!$J:$J,Summary!$G$2,Riviera_4!$B:$B,Summary!$C24,Riviera_4!$C:$C,Summary!$D24) | H24: =SUM(E24:G24)
B25: R | C25: 4 | D25: G | E25: =COUNTIFS(Riviera_4!$J:$J,Summary!$E$2,Riviera_4!$B:$B,Summary!$C25,Riviera_4!$C:$C,Summary!$D25) | F25: =COUNTIFS(Riviera_4!$J:$J,Summary!$F$2,Riviera_4!$B:$B,Summary!$C25,Riviera_4!$C:$C,Summary!$D25) | G25: =COUNTIFS(Riviera_4!$J:$J,Summary!$G$2,Riviera_4!$B:$B,Summary!$C25,Riviera_4!$C:$C,Summary!$D25) | H25: =SUM(E25:G25)
B26: R | C26: 4 | D26: H | E26: =COUNTIFS(Riviera_4!$J:$J,Summary!$E$2,Riviera_4!$B:$B,Summary!$C26,Riviera_4!$C:$C,Summary!$D26) | F26: =COUNTIFS(Riviera_4!$J:$J,Summary!$F$2,Riviera_4!$B:$B,Summary!$C26,Riviera_4!$C:$C,Summary!$D26) | G26: =COUNTIFS(Riviera_4!$J:$J,Summary!$G$2,Riviera_4!$B:$B,Summary!$C26,Riviera_4!$C:$C,Summary!$D26) | H26: =SUM(E26:G26)
B27: R | C27: 5 | D27: E | E27: =COUNTIFS(Riviera_5!$J:$J,Summary!$E$2,Riviera_5!$B:$B,Summary!$C27,Riviera_5!$C:$C,Summary!$D27) | F27: =COUNTIFS(Riviera_5!$J:$J,Summary!$F$2,Riviera_5!$B:$B,Summary!$C27,Riviera_5!$C:$C,Summary!$D27) | G27: =COUNTIFS(Riviera_5!$J:$J,Summary!$G$2,Riviera_5!$B:$B,Summary!$C27,Riviera_5!$C:$C,Summary!$D27) | H27: =SUM(E27:G27)
B28: R | C28: 5 | D28: F | E28: =COUNTIFS(Riviera_5!$J:$J,Summary!$E$2,Riviera_5!$B:$B,Summary!$C28,Riviera_5!$C:$C,Summary!$D28) | F28: =COUNTIFS(Riviera_5!$J:$J,Summary!$F$2,Riviera_5!$B:$B,Summary!$C28,Riviera_5!$C:$C,Summary!$D28) | G28: =COUNTIFS(Riviera_5!$J:$J,Summary!$G$2,Riviera_5!$B:$B,Summary!$C28,Riviera_5!$C:$C,Summary!$D28) | H28: =SUM(E28:G28)
B29: R | C29: 5 | D29: G | E29: =COUNTIFS(Riviera_5!$J:$J,Summary!$E$2,Riviera_5!$B:$B,Summary!$C29,Riviera_5!$C:$C,Summary!$D29) | F29: =COUNTIFS(Riviera_5!$J:$J,Summary!$F$2,Riviera_5!$B:$B,Summary!$C29,Riviera_5!$C:$C,Summary!$D29) | G29: =COUNTIFS(Riviera_5!$J:$J,Summary!$G$2,Riviera_5!$B:$B,Summary!$C29,Riviera_5!$C:$C,Summary!$D29) | H29: =SUM(E29:G29)
B30: R | C30: 5 | D30: H | E30: =COUNTIFS(Riviera_5!$J:$J,Summary!$E$2,Riviera_5!$B:$B,Summary!$C30,Riviera_5!$C:$C,Summary!$D30) | F30: =COUNTIFS(Riviera_5!$J:$J,Summary!$F$2,Riviera_5!$B:$B,Summary!$C30,Riviera_5!$C:$C,Summary!$D30) | G30: =COUNTIFS(Riviera_5!$J:$J,Summary!$G$2,Riviera_5!$B:$B,Summary!$C30,Riviera_5!$C:$C,Summary!$D30) | H30: =SUM(E30:G30)
B32: TOTAL | E32: =SUBTOTAL(9,E3:E30) | F32: =SUBTOTAL(9,F3:F30) | G32: =SUBTOTAL(9,G3:G30) | H32: =SUBTOTAL(9,H3:H30)

Sheet Tower_3
A1: Building | B1: Floor | C1: Area | D1: Desk Number | E1: Row | F1: Desk number | G1: Associate Staff ID - INPUT | H1: Associate Name | I1: 1st line Supervisor | J1: Desk Status | M1: Floor Plan
A2: T | B2: 3 | C2: A | D2: 00 | E2: 1 | F2: =A2&B2&"-"&C2&E2&"-"&D2 | G2: 1194 | H2: =_xlfn.XLOOKUP(G2,'All Associates'!A:A,'All Associates'!B:B) | I2: =_xlfn.XLOOKUP(G2,'All Associates'!A:A,'All Associates'!D:D) | J2: =IF(G2<>"","Allocated","Available")
A3: T | B3: 3 | C3: A | D3: 01 | E3: 1 | F3: =A3&B3&"-"&C3&E3&"-"&D3 | G3: 935 | H3: =_xlfn.XLOOKUP(G3,'All Associates'!A:A,'All Associates'!B:B) | I3: =_xlfn.XLOOKUP(G3,'All Associates'!A:A,'All Associates'!D:D) | J3: =IF(G3<>"","Allocated","Available")
A4: T | B4: 3 | C4: A | D4: 02 | E4: 1 | F4: =A4&B4&"-"&C4&E4&"-"&D4 | G4: 687 | H4: =_xlfn.XLOOKUP(G4,'All Associates'!A:A,'All Associates'!B:B) | I4: =_xlfn.XLOOKUP(G4,'All Associates'!A:A,'All Associates'!D:D) | J4: =IF(G4<>"","Allocated","Available")
A5: T | B5: 3 | C5: A | D5: 03 | E5: 1 | F5: =A5&B5&"-"&C5&E5&"-"&D5 | G5: 685 | H5: =_xlfn.XLOOKUP(G5,'All Associates'!A:A,'All Associates'!B:B) | I5: =_xlfn.XLOOKUP(G5,'All Associates'!A:A,'All Associates'!D:D) | J5: =IF(G5<>"","Allocated","Available")
A6: T | B6: 3 | C6: A | D6: 04 | E6: 1 | F6: =A6&B6&"-"&C6&E6&"-"&D6 | G6: 1227 | H6: =_xlfn.XLOOKUP(G6,'All Associates'!A:A,'All Associates'!B:B) | I6: =_xlfn.XLOOKUP(G6,'All Associates'!A:A,'All Associates'!D:D) | J6: =IF(G6<>"","Allocated","Available")
A7: T | B7: 3 | C7: A | D7: 05 | E7: 1 | F7: =A7&B7&"-"&C7&E7&"-"&D7 | G7: 1216 | H7: =_xlfn.XLOOKUP(G7,'All Associates'!A:A,'All Associates'!B:B) | I7: =_xlfn.XLOOKUP(G7,'All Associates'!A:A,'All Associates'!D:D) | J7: =IF(G7<>"","Allocated","Available")
A8: T | B8: 3 | C8: A | D8: 06 | E8: 1 | F8: =A8&B8&"-"&C8&E8&"-"&D8 | H8: =_xlfn.XLOOKUP(G8,'All Associates'!A:A,'All Associates'!B:B) | I8: =_xlfn.XLOOKUP(G8,'All Associates'!A:A,'All Associates'!D:D) | J8: =IF(G8<>"","Allocated","Available")
A9: T | B9: 3 | C9: A | D9: 07 | E9: 1 | F9: =A9&B9&"-"&C9&E9&"-"&D9
A10: T | B10: 3 | C10: A | D10: 08 | E10: 1 | F10: =A10&B10&"-"&C10&E10&"-"&D10
A11: T | B11: 3 | C11: A | D11: 01 | E11: 2 | F11: =A11&B11&"-"&C11&E11&"-"&D11 | G11: 932 | H11: =_xlfn.XLOOKUP(G11,'All Associates'!A:A,'All Associates'!B:B) | I11: =_xlfn.XLOOKUP(G11,'All Associates'!A:A,'All Associates'!D:D) | J11: =IF(G11<>"","Allocated","Available")
A12: T | B12: 3 | C12: A | D12: 02 | E12: 2 | F12: =A12&B12&"-"&C12&E12&"-"&D12 | G12: 994 | H12: =_xlfn.XLOOKUP(G12,'All Associates'!A:A,'All Associates'!B:B) | I12: =_xlfn.XLOOKUP(G12,'All Associates'!A:A,'All Associates'!D:D) | J12: =IF(G12<>"","Allocated","Available")
A13: T | B13: 3 | C13: A | D13: 03 | E13: 2 | F13: =A13&B13&"-"&C13&E13&"-"&D13 | G13: 487 | H13: =_xlfn.XLOOKUP(G13,'All Associates'!A:A,'All Associates'!B:B) | I13: =_xlfn.XLOOKUP(G13,'All Associates'!A:A,'All Associates'!D:D) | J13: =IF(G13<>"","Allocated","Available")
A14: T | B14: 3 | C14: A | D14: 04 | E14: 2 | F14: =A14&B14&"-"&C14&E14&"-"&D14 | G14: 128 | H14: =_xlfn.XLOOKUP(G14,'All Associates'!A:A,'All Associates'!B:B) | I14: =_xlfn.XLOOKUP(G14,'All Associates'!A:A,'All Associates'!D:D) | J14: =IF(G14<>"","Allocated","Available")
A15: T | B15: 3 | C15: A | D15: 05 | E15: 2 | F15: =A15&B15&"-"&C15&E15&"-"&D15 | H15: =_xlfn.XLOOKUP(G15,'All Associates'!A:A,'All Associates'!B:B) | I15: =_xlfn.XLOOKUP(G15,'All Associates'!A:A,'All Associates'!D:D) | J15: =IF(G15<>"","Allocated","Available")
A16: T | B16: 3 | C16: A | D16: 06 | E16: 2 | F16: =A16&B16&"-"&C16&E16&"-"&D16 | H16: =_xlfn.XLOOKUP(G16,'All Associates'!A:A,'All Associates'!B:B) | I16: =_xlfn.XLOOKUP(G16,'All Associates'!A:A,'All Associates'!D:D)
A17: T | B17: 3 | C17: A | D17: 07 | E17: 2 | F17: =A17&B17&"-"&C17&E17&"-"&D17
A18: T | B18: 3 | C18: A | D18: 08 | E18: 2 | F18: =A18&B18&"-"&C18&E18&"-"&D18
A19: T | B19: 3 | C19: A | D19: 01 | E19: 3 | F19: =A19&B19&"-"&C19&E19&"-"&D19 | J19: NA
A20: T | B20: 3 | C20: A | D20: 01 | E20: M1 | F20: =A20&B20&"-"&C20&E20&"-"&D20 | G20: 1 | H20: =_xlfn.XLOOKUP(G20,'All Associates'!A:A,'All Associates'!B:B) | I20: =_xlfn.XLOOKUP(G20,'All Associates'!A:A,'All Associates'!D:D) | J20: =IF(G20<>"","Allocated","Available")
A21: T | B21: 3 | C21: B | D21: 01 | E21: 1 | F21: =A21&B21&"-"&C21&E21&"-"&D21 | G21: 929 | H21: =_xlfn.XLOOKUP(G21,'All Associates'!A:A,'All Associates'!B:B) | I21: =_xlfn.XLOOKUP(G21,'All Associates'!A:A,'All Associates'!D:D) | J21: HW
A22: T | B22: 3 | C22: B | D22: 02 | E22: 1 | F22: =A22&B22&"-"&C22&E22&"-"&D22 | G22: 577 | H22: =_xlfn.XLOOKUP(G22,'All Associates'!A:A,'All Associates'!B:B) | I22: =_xlfn.XLOOKUP(G22,'All Associates'!A:A,'All Associates'!D:D) | J22: HW
A23: T | B23: 3 | C23: B | D23: 03 | E23: 1 | F23: =A23&B23&"-"&C23&E23&"-"&D23 | G23: 964 | H23: =_xlfn.XLOOKUP(G23,'All Associates'!A:A,'All Associates'!B:B) | I23: =_xlfn.XLOOKUP(G23,'All Associates'!A:A,'All Associates'!D:D) | J23: HW
A24: T | B24: 3 | C24: B | D24: 04 | E24: 1 | F24: =A24&B24&"-"&C24&E24&"-"&D24 | H24: =_xlfn.XLOOKUP(G24,'All Associates'!A:A,'All Associates'!B:B) | I24: =_xlfn.XLOOKUP(G24,'All Associates'!A:A,'All Associates'!D:D) | J24: HW
A25: T | B25: 3 | C25: B | D25: 01 | E25: M1 | F25: =A25&B25&"-"&C25&E25&"-"&D25 | G25: 1112 | H25: =_xlfn.XLOOKUP(G25,'All Associates'!A:A,'All Associates'!B:B) | I25: =_xlfn.XLOOKUP(G25,'All Associates'!A:A,'All Associates'!D:D) | J25: =IF(G25<>"","Allocated","Available")
A26: T | B26: 3 | C26: C | D26: 01 | E26: 1 | F26: =A26&B26&"-"&C26&E26&"-"&D26 | G26: 446 | H26: =_xlfn.XLOOKUP(G26,'All Associates'!A:A,'All Associates'!B:B) | I26: =_xlfn.XLOOKUP(G26,'All Associates'!A:A,'All Associates'!D:D) | J26: =IF(G26<>"","Allocated","Available")
A27: T | B27: 3 | C27: C | D27: 02 | E27: 1 | F27: =A27&B27&"-"&C27&E27&"-"&D27 | G27: 860 | H27: =_xlfn.XLOOKUP(G27,'All Associates'!A:A,'All Associates'!B:B) | I27: =_xlfn.XLOOKUP(G27,'All Associates'!A:A,'All Associates'!D:D) | J27: =IF(G27<>"","Allocated","Available")
A28: T | B28: 3 | C28: C | D28: 03 | E28: 1 | F28: =A28&B28&"-"&C28&E28&"-"&D28 | G28: 1228 | H28: =_xlfn.XLOOKUP(G28,'All Associates'!A:A,'All Associates'!B:B) | I28: =_xlfn.XLOOKUP(G28,'All Associates'!A:A,'All Associates'!D:D) | J28: =IF(G28<>"","Allocated","Available")
A29: T | B29: 3 | C29: C | D29: 04 | E29: 1 | F29: =A29&B29&"-"&C29&E29&"-"&D29 | G29: 1140 | H29: =_xlfn.XLOOKUP(G29,'All Associates'!A:A,'All Associates'!B:B) | I29: =_xlfn.XLOOKUP(G29,'All Associates'!A:A,'All Associates'!D:D) | J29: =IF(G29<>"","Allocated","Available")
A30: T | B30: 3 | C30: C | D30: 05 | E30: 1 | F30: =A30&B30&"-"&C30&E30&"-"&D30 | G30: 418 | H30: =_xlfn.XLOOKUP(G30,'All Associates'!A:A,'All Associates'!B:B) | I30: =_xlfn.XLOOKUP(G30,'All Associates'!A:A,'All Associates'!D:D) | J30: =IF(G30<>"","Allocated","Available")
A31: T | B31: 3 | C31: C | D31: 06 | E31: 1 | F31: =A31&B31&"-"&C31&E31&"-"&D31 | G31: 2012 | H31: =_xlfn.XLOOKUP(G31,'All Associates'!A:A,'All Associates'!B:B) | I31: =_xlfn.XLOOKUP(G31,'All Associates'!A:A,'All Associates'!D:D) | J31: =IF(G31<>"","Allocated","Available")
A32: T | B32: 3 | C32: C | D32: 07 | E32: 1 | F32: =A32&B32&"-"&C32&E32&"-"&D32 | G32: 506 | H32: =_xlfn.XLOOKUP(G32,'All Associates'!A:A,'All Associates'!B:B) | I32: =_xlfn.XLOOKUP(G32,'All Associates'!A:A,'All Associates'!D:D) | J32: =IF(G32<>"","Allocated","Available")
A33: T | B33: 3 | C33: C | D33: 08 | E33: 1 | F33: =A33&B33&"-"&C33&E33&"-"&D33 | G33: 909 | H33: =_xlfn.XLOOKUP(G33,'All Associates'!A:A,'All Associates'!B:B) | I33: =_xlfn.XLOOKUP(G33,'All Associates'!A:A,'All Associates'!D:D) | J33: =IF(G33<>"","Allocated","Available")
A34: T | B34: 3 | C34: C | D34: 01 | E34: 2 | F34: =A34&B34&"-"&C34&E34&"-"&D34 | G34: 1034 | H34: =_xlfn.XLOOKUP(G34,'All Associates'!A:A,'All Associates'!B:B) | I34: =_xlfn.XLOOKUP(G34,'All Associates'!A:A,'All Associates'!D:D) | J34: =IF(G34<>"","Allocated","Available")
A35: T | B35: 3 | C35: C | D35: 02 | E35: 2 | F35: =A35&B35&"-"&C35&E35&"-"&D35 | G35: 1215 | H35: =_xlfn.XLOOKUP(G35,'All Associates'!A:A,'All Associates'!B:B) | I35: =_xlfn.XLOOKUP(G35,'All Associates'!A:A,'All Associates'!D:D) | J35: =IF(G35<>"","Allocated","Available")
A36: T | B36: 3 | C36: C | D36: 03 | E36: 2 | F36: =A36&B36&"-"&C36&E36&"-"&D36 | G36: 750 | H36: =_xlfn.XLOOKUP(G36,'All Associates'!A:A,'All Associates'!B:B) | I36: =_xlfn.XLOOKUP(G36,'All Associates'!A:A,'All Associates'!D:D) | J36: =IF(G36<>"","Allocated","Available")
A37: T | B37: 3 | C37: C | D37: 04 | E37: 2 | F37: =A37&B37&"-"&C37&E37&"-"&D37 | G37: 1100 | H37: =_xlfn.XLOOKUP(G37,'All Associates'!A:A,'All Associates'!B:B) | I37: =_xlfn.XLOOKUP(G37,'All Associates'!A:A,'All Associates'!D:D) | J37: =IF(G37<>"","Allocated","Available")
A38: T | B38: 3 | C38: C | D38: 05 | E38: 2 | F38: =A38&B38&"-"&C38&E38&"-"&D38 | H38: =_xlfn.XLOOKUP(G38,'All Associates'!A:A,'All Associates'!B:B) | I38: =_xlfn.XLOOKUP(G38,'All Associates'!A:A,'All Associates'!D:D) | J38: =IF(G38<>"","Allocated","Available")
A39: T | B39: 3 | C39: C | D39: 06 | E39: 2 | F39: =A39&B39&"-"&C39&E39&"-"&D39 | H39: =_xlfn.XLOOKUP(G39,'All Associates'!A:A,'All Associates'!B:B) | I39: =_xlfn.XLOOKUP(G39,'All Associates'!A:A,'All Associates'!D:D) | J39: =IF(G39<>"","Allocated","Available")
A40: T | B40: 3 | C40: C | D40: 07 | E40: 2 | F40: =A40&B40&"-"&C40&E40&"-"&D40 | H40: =_xlfn.XLOOKUP(G40,'All Associates'!A:A,'All Associates'!B:B) | I40: =_xlfn.XLOOKUP(G40,'All Associates'!A:A,'All Associates'!D:D) | J40: =IF(G40<>"","Allocated","Available")
...

Sheet Tower_4
A1: Building | B1: Floor | C1: Area | D1: Desk Number | E1: Row | F1: Desk number | G1: Associate Staff ID - INPUT | H1: Associate Name | I1: 1st line Supervisor | J1: Desk Status | M1: Floor Plan
A2: T | B2: 4 | C2: A | D2: 01 | E2: 1 | F2: =A2&B2&"-"&C2&E2&"-"&D2 | G2: 366 | H2: =_xlfn.XLOOKUP(G2,'All Associates'!A:A,'All Associates'!B:B) | I2: =_xlfn.XLOOKUP(G2,'All Associates'!A:A,'All Associates'!D:D) | J2: =IF(G2<>"","Allocated","Available")
A3: T | B3: 4 | C3: A | D3: 02 | E3: 1 | F3: =A3&B3&"-"&C3&E3&"-"&D3 | G3: 790 | H3: =_xlfn.XLOOKUP(G3,'All Associates'!A:A,'All Associates'!B:B) | I3: =_xlfn.XLOOKUP(G3,'All Associates'!A:A,'All Associates'!D:D) | J3: =IF(G3<>"","Allocated","Available")
A4: T | B4: 4 | C4: A | D4: 03 | E4: 1 | F4: =A4&B4&"-"&C4&E4&"-"&D4 | G4: 781 | H4: =_xlfn.XLOOKUP(G4,'All Associates'!A:A,'All Associates'!B:B) | I4: =_xlfn.XLOOKUP(G4,'All Associates'!A:A,'All Associates'!D:D) | J4: =IF(G4<>"","Allocated","Available")
A5: T | B5: 4 | C5: A | D5: 04 | E5: 1 | F5: =A5&B5&"-"&C5&E5&"-"&D5 | G5: 711 | H5: =_xlfn.XLOOKUP(G5,'All Associates'!A:A,'All Associates'!B:B) | I5: =_xlfn.XLOOKUP(G5,'All Associates'!A:A,'All Associates'!D:D) | J5: =IF(G5<>"","Allocated","Available")
A6: T | B6: 4 | C6: A | D6: 05 | E6: 1 | F6: =A6&B6&"-"&C6&E6&"-"&D6 | G6: 867 | H6: =_xlfn.XLOOKUP(G6,'All Associates'!A:A,'All Associates'!B:B) | I6: =_xlfn.XLOOKUP(G6,'All Associates'!A:A,'All Associates'!D:D) | J6: =IF(G6<>"","Allocated","Available")
A7: T | B7: 4 | C7: A | D7: 06 | E7: 1 | F7: =A7&B7&"-"&C7&E7&"-"&D7 | G7: 2004 | H7: =_xlfn.XLOOKUP(G7,'All Associates'!A:A,'All Associates'!B:B) | I7: =_xlfn.XLOOKUP(G7,'All Associates'!A:A,'All Associates'!D:D) | J7: =IF(G7<>"","Allocated","Available")
A8: T | B8: 4 | C8: A | D8: 07 | E8: 1 | F8: =A8&B8&"-"&C8&E8&"-"&D8 | G8: 483 | H8: =_xlfn.XLOOKUP(G8,'All Associates'!A:A,'All Associates'!B:B) | I8: =_xlfn.XLOOKUP(G8,'All Associates'!A:A,'All Associates'!D:D) | J8: =IF(G8<>"","Allocated","Available")
A9: T | B9: 4 | C9: A | D9: 08 | E9: 1 | F9: =A9&B9&"-"&C9&E9&"-"&D9 | G9: 2031 | H9: =_xlfn.XLOOKUP(G9,'All Associates'!A:A,'All Associates'!B:B) | I9: =_xlfn.XLOOKUP(G9,'All Associates'!A:A,'All Associates'!D:D) | J9: =IF(G9<>"","Allocated","Available")
A10: T | B10: 4 | C10: A | D10: 01 | E10: 2 | F10: =A10&B10&"-"&C10&E10&"-"&D10 | G10: 379 | H10: =_xlfn.XLOOKUP(G10,'All Associates'!A:A,'All Associates'!B:B) | I10: =_xlfn.XLOOKUP(G10,'All Associates'!A:A,'All Associates'!D:D) | J10: =IF(G10<>"","Allocated","Available")
A11: T | B11: 4 | C11: A | D11: 02 | E11: 2 | F11: =A11&B11&"-"&C11&E11&"-"&D11 | G11: 368 | H11: =_xlfn.XLOOKUP(G11,'All Associates'!A:A,'All Associates'!B:B) | I11: =_xlfn.XLOOKUP(G11,'All Associates'!A:A,'All Associates'!D:D) | J11: =IF(G11<>"","Allocated","Available")
A12: T | B12: 4 | C12: A | D12: 03 | E12: 2 | F12: =A12&B12&"-"&C12&E12&"-"&D12 | G12: 70 | H12: =_xlfn.XLOOKUP(G12,'All Associates'!A:A,'All Associates'!B:B) | I12: =_xlfn.XLOOKUP(G12,'All Associates'!A:A,'All Associates'!D:D) | J12: =IF(G12<>"","Allocated","Available")
A13: T | B13: 4 | C13: A | D13: 04 | E13: 2 | F13: =A13&B13&"-"&C13&E13&"-"&D13 | G13: 851 | H13: =_xlfn.XLOOKUP(G13,'All Associates'!A:A,'All Associates'!B:B) | I13: =_xlfn.XLOOKUP(G13,'All Associates'!A:A,'All Associates'!D:D) | J13: =IF(G13<>"","Allocated","Available")
... A25: T | B25: 4 | C25: A | D25: 08 | E25: 3 | F25: =A25&B25&"-"&C25&E25&"-"&D25 | G25: 800 | H25: =_xlfn.XLOOKUP(G25,'All Associates'!A:A,'All Associates'!B:B) | I25: =_xlfn.XLOOKUP(G25,'All Associates'!A:A,'All Associates'!D:D) | J25: =IF(G25<>"","Allocated","Available")
A26: T | B26: 4 | C26: A | D26: 1 | E26: M1 | F26: =A26&B26&"-"&C26&E26&"-"&D26 | G26: 343 | H26: =_xlfn.XLOOKUP(G26,'All Associates'!A:A,'All Associates'!B:B) | I26: =_xlfn.XLOOKUP(G26,'All Associates'!A:A,'All Associates'!D:D) | J26: =IF(G26<>"","Allocated","Available")
A27: T | B27: 4 | C27: A | D27: 1 | E27: 4 | F27: =A27&B27&"-"&C27&E27&"-"&D27 | G27: 2026 | H27: =_xlfn.XLOOKUP(G27,'All Associates'!A:A,'All Associates'!B:B) | I27: =_xlfn.XLOOKUP(G27,'All Associates'!A:A,'All Associates'!D:D) | J27: =IF(G27<>"","Allocated","Available")
A28: T | B28: 4 | C28: A | D28: 2 | E28: 4 | F28: =A28&B28&"-"&C28&E28&"-"&D28 | H28: =_xlfn.XLOOKUP(G28,'All Associates'!A:A,'All Associates'!B:B) | I28: =_xlfn.XLOOKUP(G28,'All Associates'!A:A,'All Associates'!D:D) | J28: =IF(G28<>"","Allocated","Available")
A29: T | B29: 4 | C29: A | D29: 3 | E29: 4 | F29: =A29&B29&"-"&C29&E29&"-"&D29 | G29: 2027 | H29: =_xlfn.XLOOKUP(G29,'All Associates'!A:A,'All Associates'!B:B) | I29: =_xlfn.XLOOKUP(G29,'All Associates'!A:A,'All Associates'!D:D) | J29: =IF(G29<>"","Allocated","Available")
A30: T | B30: 4 | C30: A | D30: 4 | E30: 4 | F30: =A30&B30&"-"&C30&E30&"-"&D30 | H30: =_xlfn.XLOOKUP(G30,'All Associates'!A:A,'All Associates'!B:B) | I30: =_xlfn.XLOOKUP(G30,'All Associates'!A:A,'All Associates'!D:D) | J30: =IF(G30<>"","Allocated","Available")
A31: T | B31: 4 | C31: B | D31: 01 | E31: 1 | F31: =A31&B31&"-"&C31&E31&"-"&D31 | G31: 735 | H31: =_xlfn.XLOOKUP(G31,'All Associates'!A:A,'All Associates'!B:B) | I31: =_xlfn.XLOOKUP(G31,'All Associates'!A:A,'All Associates'!D:D) | J31: =IF(G31<>"","Allocated","Available")
A32: T | B32: 4 | C32: B | D32: 02 | E32: 1 | F32: =A32&B32&"-"&C32&E32&"-"&D32 | G32: 478 | H32: =_xlfn.XLOOKUP(G32,'All Associates'!A:A,'All Associates'!B:B) | I32: =_xlfn.XLOOKUP(G32,'All Associates'!A:A,'All Associates'!D:D) | J32: =IF(G32<>"","Allocated","Available")
A33: T | B33: 4 | C33: B | D33: 03 | E33: 1 | F33: =A33&B33&"-"&C33&E33&"-"&D33 | G33: 806 | H33: =_xlfn.XLOOKUP(G33,'All Associates'!A:A,'All Associates'!B:B) | I33: =_xlfn.XLOOKUP(G33,'All Associates'!A:A,'All Associates'!D:D) | J33: =IF(G33<>"","Allocated","Available")
A34: T | B34: 4 | C34: B | D34: 04 | E34: 1 | F34: =A34&B34&"-"&C34&E34&"-"&D34 | G34: 2029 | H34: =_xlfn.XLOOKUP(G34,'All Associates'!A:A,'All Associates'!B:B) | I34: =_xlfn.XLOOKUP(G34,'All Associates'!A:A,'All Associates'!D:D) | J34: =IF(G34<>"","Allocated","Available")
A35: T | B35: 4 | C35: B | D35: 05 | E35: 1 | F35: =A35&B35&"-"&C35&E35&"-"&D35 | G35: 185 | H35: =_xlfn.XLOOKUP(G35,'All Associates'!A:A,'All Associates'!B:B) | I35: =_xlfn.XLOOKUP(G35,'All Associates'!A:A,'All Associates'!D:D) | J35: =IF(G35<>"","Allocated","Available")
A36: T | B36: 4 | C36: B | D36: 01 | E36: 2 | F36: =A36&B36&"-"&C36&E36&"-"&D36 | G36: 431 | H36: =_xlfn.XLOOKUP(G36,'All Associates'!A:A,'All Associates'!B:B) | I36: =_xlfn.XLOOKUP(G36,'All Associates'!A:A,'All Associates'!D:D) | J36: =IF(G36<>"","Allocated","Available")
A37: T | B37: 4 | C37: B | D37: 02 | E37: 2 | F37: =A37&B37&"-"&C37&E37&"-"&D37 | G37: 852 | H37: =_xlfn.XLOOKUP(G37,'All Associates'!A:A,'All Associates'!B:B) | I37: =_xlfn.XLOOKUP(G37,'All Associates'!A:A,'All Associates'!D:D) | J37: =IF(G37<>"","Allocated","Available")
A38: T | B38: 4 | C38: B | D38: 03 | E38: 2 | F38: =A38&B38&"-"&C38&E38&"-"&D38 | G38: 1003 | H38: =_xlfn.XLOOKUP(G38,'All Associates'!A:A,'All Associates'!B:B) | I38: =_xlfn.XLOOKUP(G38,'All Associates'!A:A,'All Associates'!D:D) | J38: =IF(G38<>"","Allocated","Available")
A39: T | B39: 4 | C39: B | D39: 04 | E39: 2 | F39: =A39&B39&"-"&C39&E39&"-"&D39 | G39: 859 | H39: =_xlfn.XLOOKUP(G39,'All Associates'!A:A,'All Associates'!B:B) | I39: =_xlfn.XLOOKUP(G39,'All Associates'!A:A,'All Associates'!D:D) | J39: =IF(G39<>"","Allocated","Available")
A40: T | B40: 4 | C40: B | D40: 05 | E40: 2 | F40: =A40&B40&"-"&C40&E40&"-"&D40 | G40: 1167 | H40: =_xlfn.XLOOKUP(G40,'All Associates'!A:A,'All Associates'!B:B) | I40: =_xlfn.XLOOKUP(G40,'All Associates'!A:A,'All Associates'!D:D) | J40: =IF(G40<>"","Allocated","Available")
A41: T | B41: 4 | C41: B | D41: 06 | E41: 2 | F41: =A41&B41&"-"&C41&E41&"-"&D41 | H41: =_xlfn.XLOOKUP(G41,'All Associates'!A:A,'All Associates'!B:B) | I41: =_xlfn.XLOOKUP(G41,'All Associates'!A:A,'All Associates'!D:D) | J41: =IF(G41<>"","Allocated","Available")
A42: T | B42: 4 | C42: C | D42: 01 | E42: 1 | F42: =A42&B42&"-"&C42&E42&"-"&D42 | G42: 531 | H42: =_xlfn.XLOOKUP(G42,'All Associates'!A:A,'All Associates'!B:B) | I42: =_xlfn.XLOOKUP(G42,'All Associates'!A:A,'All Associates'!D:D) | J42: =IF(G42<>"","Allocated","Available")
A43: T | B43: 4 | C43: C | D43: 02 | E43: 1 | F43: =A43&B43&"-"&C43&E43&"-"&D43 | G43: 1113 | H43: =_xlfn.XLOOKUP(G43,'All Associates'!A:A,'All Associates'!B:B) | I43: =_xlfn.XLOOKUP(G43,'All Associates'!A:A,'All Associates'!D:D) | J43: =IF(G43<>"","Allocated","Available")
A44: T | B44: 4 | C44: C | D44: 03 | E44: 1 | F44: =A44&B44&"-"&C44&E44&"-"&D44 | G44: 725 | H44: =_xlfn.XLOOKUP(G44,'All Associates'!A:A,'All Associates'!B:B) | I44: =_xlfn.XLOOKUP(G44,'All Associates'!A:A,'All Associates'!D:D) | J44: =IF(G44<>"","Allocated","Available")
A45: T | B45: 4 | C45: C | D45: 04 | E45: 1 | F45: =A45&B45&"-"&C45&E45&"-"&D45 | G45: 227 | H45: =_xlfn.XLOOKUP(G45,'All Associates'!A:A,'All Associates'!B:B) | I45: =_xlfn.XLOOKUP(G45,'All Associates'!A:A,'All Associates'!D:D) | J45: =IF(G45<>"","Allocated","Available")
A46: T | B46: 4 | C46: C | D46: 05 | E46: 1 | F46: =A46&B46&"-"&C46&E46&"-"&D46 | G46: 355 | H46: =_xlfn.XLOOKUP(G46,'All Associates'!A:A,'All Associates'!B:B) | I46: =_xlfn.XLOOKUP(G46,'All Associates'!A:A,'All Associates'!D:D) | J46: =IF(G46<>"","Allocated","Available")
A47: T | B47: 4 | C47: C | D47: 06 | E47: 1 | F47: =A47&B47&"-"&C47&E47&"-"&D47 | G47: 460 | H47: =_xlfn.XLOOKUP(G47,'All Associates'!A:A,'All Associates'!B:B) | I47: =_xlfn.XLOOKUP(G47,'All Associates'!A:A,'All Associates'!D:D) | J47: =IF(G47<>"","Allocated","Available")
A48: T | B48: 4 | C48: C | D48: 01 | E48: 2 | F48: =A48&B48&"-"&C48&E48&"-"&D48 | G48: 1093 | H48: =_xlfn.XLOOKUP(G48,'All Associates'!A:A,'All Associates'!B:B) | I48: =_xlfn.XLOOKUP(G48,'All Associates'!A:A,'All Associates'!D:D) | J48: =IF(G48<>"","Allocated","Available")
A49: T | B49: 4 | C49: C | D49: 02 | E49: 2 | F49: =A49&B49&"-"&C49&E49&"-"&D49 | G49: 1145 | H49: =_xlfn.XLOOKUP(G49,'All Associates'!A:A,'All Associates'!B:B) | I49: =_xlfn.XLOOKUP(G49,'All Associates'!A:A,'All Associates'!D:D) | J49: =IF(G49<>"","Allocated","Available")
A50: T | B50: 4 | C50: C | D50: 03 | E50: 2 | F50: =A50&B50&"-"&C50&E50&"-"&D50 | G50: 775 | H50: =_xlfn.XLOOKUP(G50,'All Associates'!A:A,'All Associates'!B:B) | I50: =_xlfn.XLOOKUP(G50,'All Associates'!A:A,'All Associates'!D:D) | J50: =IF(G50<>"","Allocated","Available")
A51: T | B51: 4 | C51: C | D51: 04 | E51: 2 | F51: =A51&B51&"-"&C51&E51&"-"&D51 | H51: =_xlfn.XLOOKUP(G51,'All Associates'!A:A,'All Associates'!B:B) | I51: =_xlfn.XLOOKUP(G51,'All Associates'!A:A,'All Associates'!D:D) | J51: =IF(G51<>"","Allocated","Available")
...

Sheet Tower_5
A1: Building | B1: Floor | C1: Area | D1: Desk Number | E1: Row | F1: Desk number | G1: Associate Staff ID - INPUT | H1: Associate Name | I1: 1st line Supervisor | J1: Desk Status | M1: Floor Plan
A2: T | B2: 5 | C2: A | D2: 01 | E2: 1 | F2: =A2&B2&"-"&C2&E2&"-"&D2 | H2: =_xlfn.XLOOKUP(G2,'All Associates'!A:A,'All Associates'!B:B) | I2: =_xlfn.XLOOKUP(G2,'All Associates'!A:A,'All Associates'!D:D) | J2: =IF(G2<>"","Allocated","Available")
A3: T | B3: 5 | C3: A | D3: 02 | E3: 1 | F3: =A3&B3&"-"&C3&E3&"-"&D3 | G3: 796 | H3: =_xlfn.XLOOKUP(G3,'All Associates'!A:A,'All Associates'!B:B) | I3: =_xlfn.XLOOKUP(G3,'All Associates'!A:A,'All Associates'!D:D) | J3: =IF(G3<>"","Allocated","Available")
A4: T | B4: 5 | C4: A | D4: 03 | E4: 1 | F4: =A4&B4&"-"&C4&E4&"-"&D4 | G4: 887 | H4: =_xlfn.XLOOKUP(G4,'All Associates'!A:A,'All Associates'!B:B) | I4: =_xlfn.XLOOKUP(G4,'All Associates'!A:A,'All Associates'!D:D) | J4: =IF(G4<>"","Allocated","Available")
A5: T | B5: 5 | C5: A | D5: 04 | E5: 1 | F5: =A5&B5&"-"&C5&E5&"-"&D5 | G5: 789 | H5: =_xlfn.XLOOKUP(G5,'All Associates'!A:A,'All Associates'!B:B) | I5: =_xlfn.XLOOKUP(G5,'All Associates'!A:A,'All Associates'!D:D) | J5: =IF(G5<>"","Allocated","Available")
A6: T | B6: 5 | C6: A | D6: 05 | E6: 1 | F6: =A6&B6&"-"&C6&E6&"-"&D6 | G6: 726 | H6: =_xlfn.XLOOKUP(G6,'All Associates'!A:A,'All Associates'!B:B) | I6: =_xlfn.XLOOKUP(G6,'All Associates'!A:A,'All Associates'!D:D) | J6: =IF(G6<>"","Allocated","Available")
A7: T | B7: 5 | C7: A | D7: 06 | E7: 1 | F7: =A7&B7&"-"&C7&E7&"-"&D7 | G7: 1027 | H7: =_xlfn.XLOOKUP(G7,'All Associates'!A:A,'All Associates'!B:B) | I7: =_xlfn.XLOOKUP(G7,'All Associates'!A:A,'All Associates'!D:D) | J7: =IF(G7<>"","Allocated","Available")
A8: T | B8: 5 | C8: A | D8: 07 | E8: 1 | F8: =A8&B8&"-"&C8&E8&"-"&D8 | G8: 1154 | H8: =_xlfn.XLOOKUP(G8,'All Associates'!A:A,'All Associates'!B:B) | I8: =_xlfn.XLOOKUP(G8,'All Associates'!A:A,'All Associates'!D:D) | J8: =IF(G8<>"","Allocated","Available")
A9: T | B9: 5 | C9: A | D9: 08 | E9: 1 | F9: =A9&B9&"-"&C9&E9&"-"&D9 | G9: 1203 | H9: =_xlfn.XLOOKUP(G9,'All Associates'!A:A,'All Associates'!B:B) | I9: =_xlfn.XLOOKUP(G9,'All Associates'!A:A,'All Associates'!D:D) | J9: =IF(G9<>"","Allocated","Available")
A10: T | B10: 5 | C10: A | D10: 01 | E10: 2 | F10: =A10&B10&"-"&C10&E10&"-"&D10 | G10: 481 | H10: =_xlfn.XLOOKUP(G10,'All Associates'!A:A,'All Associates'!B:B) | I10: =_xlfn.XLOOKUP(G10,'All Associates'!A:A,'All Associates'!D:D) | J10: =IF(G10<>"","Allocated","Available")
A11: T | B11: 5 | C11: A | D11: 02 | E11: 2 | F11: =A11&B11&"-"&C11&E11&"-"&D11 | G11: 345 | H11: =_xlfn.XLOOKUP(G11,'All Associates'!A:A,'All Associates'!B:B) | I11: =_xlfn.XLOOKUP(G11,'All Associates'!A:A,'All Associates'!D:D) | J11: =IF(G11<>"","Allocated","Available")
A12: T | B12: 5 | C12: A | D12: 03 | E12: 2 | F12: =A12&B12&"-"&C12&E12&"-"&D12 | G12: 963 | H12: =_xlfn.XLOOKUP(G12,'All Associates'!A:A,'All Associates'!B:B) | I12: =_xlfn.XLOOKUP(G12,'All Associates'!A:A,'All Associates'!D:D) | J12: =IF(G12<>"","Allocated","Available")
A13: T | B13: 5 | C13: A | D13: 04 | E13: 2 | F13: =A13&B13&"-"&C13&E13&"-"&D13 | G13: 951 | H13: =_xlfn.XLOOKUP(G13,'All Associates'!A:A,'All Associates'!B:B) | I13: =_xlfn.XLOOKUP(G13,'All Associates'!A:A,'All Associates'!D:D) | J13: =IF(G13<>"","Allocated","Available")
A14: T | B14: 5 | C14: A | D14: 05 | E14: 2 | F14: =A14&B14&"-"&C14&E14&"-"&D14 | G14: 2055 | H14: =_xlfn.XLOOKUP(G14,'All Associates'!A:A,'All Associates'!B:B) | I14: =_xlfn.XLOOKUP(G14,'All Associates'!A:A,'All Associates'!D:D) | J14: =IF(G14<>"","Allocated","Available")
... A16: T | B16: 5 | C16: A | D16: 07 | E16: 2 | F16: =A16&B16&"-"&C16&E16&"-"&D16 | G16: 2053 | H16: =_xlfn.XLOOKUP(G16,'All Associates'!A:A,'All Associates'!B:B) | I16: =_xlfn.XLOOKUP(G16,'All Associates'!A:A,'All Associates'!D:D) | J16: =IF(G16<>"","Allocated","Available")
A17: T | B17: 5 | C17: A | D17: 08 | E17: 2 | F17: =A17&B17&"-"&C17&E17&"-"&D17 | H17: =_xlfn.XLOOKUP(G17,'All Associates'!A:A,'All Associates'!B:B) | I17: =_xlfn.XLOOKUP(G17,'All Associates'!A:A,'All Associates'!D:D) | J17: =IF(G17<>"","Allocated","Available")
A18: T | B18: 5 | C18: A | D18: 01 | E18: 3 | F18: =A18&B18&"-"&C18&E18&"-"&D18 | G18: 189 | H18: =_xlfn.XLOOKUP(G18,'All Associates'!A:A,'All Associates'!B:B) | I18: =_xlfn.XLOOKUP(G18,'All Associates'!A:A,'All Associates'!D:D) | J18: =IF(G18<>"","Allocated","Available")
A19: T | B19: 5 | C19: A | D19: 02 | E19: 3 | F19: =A19&B19&"-"&C19&E19&"-"&D19 | G19: 357 | H19: =_xlfn.XLOOKUP(G19,'All Associates'!A:A,'All Associates'!B:B) | I19: =_xlfn.XLOOKUP(G19,'All Associates'!A:A,'All Associates'!D:D) | J19: =IF(G19<>"","Allocated","Available")
A20: T | B20: 5 | C20: A | D20: 03 | E20: 3 | F20: =A20&B20&"-"&C20&E20&"-"&D20 | G20: 348 | H20: =_xlfn.XLOOKUP(G20,'All Associates'!A:A,'All Associates'!B:B) | I20: =_xlfn.XLOOKUP(G20,'All Associates'!A:A,'All Associates'!D:D) | J20: =IF(G20<>"","Allocated","Available")
A21: T | B21: 5 | C21: A | D21: 04 | E21: 3 | F21: =A21&B21&"-"&C21&E21&"-"&D21 | G21: 316 | H21: =_xlfn.XLOOKUP(G21,'All Associates'!A:A,'All Associates'!B:B) | I21: =_xlfn.XLOOKUP(G21,'All Associates'!A:A,'All Associates'!D:D) | J21: =IF(G21<>"","Allocated","Available")
A22: T | B22: 5 | C22: A | D22: 05 | E22: 3 | F22: =A22&B22&"-"&C22&E22&"-"&D22 | G22: 944 | H22: =_xlfn.XLOOKUP(G22,'All Associates'!A:A,'All Associates'!B:B) | I22: =_xlfn.XLOOKUP(G22,'All Associates'!A:A,'All Associates'!D:D) | J22: =IF(G22<>"","Allocated","Available")
A23: T | B23: 5 | C23: A | D23: 06 | E23: 3 | F23: =A23&B23&"-"&C23&E23&"-"&D23 | G23: 979 | H23: =_xlfn.XLOOKUP(G23,'All Associates'!A:A,'All Associates'!B:B) | I23: =_xlfn.XLOOKUP(G23,'All Associates'!A:A,'All Associates'!D:D) | J23: =IF(G23<>"","Allocated","Available")
A24: T | B24: 5 | C24: A | D24: 07 | E24: 3 | F24: =A24&B24&"-"&C24&E24&"-"&D24 | G24: 240 | H24: =_xlfn.XLOOKUP(G24,'All Associates'!A:A,'All Associates'!B:B) | I24: =_xlfn.XLOOKUP(G24,'All Associates'!A:A,'All Associates'!D:D) | J24: =IF(G24<>"","Allocated","Available")
A25: T | B25: 5 | C25: A | D25: 08 | E25: 3 | F25: =A25&B25&"-"&C25&E25&"-"&D25 | G25: HW | H25: =_xlfn.XLOOKUP(G25,'All Associates'!A:A,'All Associates'!B:B) | I25: =_xlfn.XLOOKUP(G25,'All Associates'!A:A,'All Associates'!D:D) | J25: =IF(G25<>"","Allocated","Available")
A26: T | B26: 5 | C26: A | D26: 01 | E26: M1 | F26: =A26&B26&"-"&C26&E26&"-"&D26 | G26: 36 | H26: =_xlfn.XLOOKUP(G26,'All Associates'!A:A,'All Associates'!B:B) | I26: =_xlfn.XLOOKUP(G26,'All Associates'!A:A,'All Associates'!D:D) | J26: =IF(G26<>"","Allocated","Available")
A27: T | B27: 5 | C27: A | D27: 01 | E27: 4 | F27: =A27&B27&"-"&C27&E27&"-"&D27 | G27: 2046 | H27: =_xlfn.XLOOKUP(G27,'All Associates'!A:A,'All Associates'!B:B) | I27: =_xlfn.XLOOKUP(G27,'All Associates'!A:A,'All Associates'!D:D) | J27: =IF(G27<>"","Allocated","Available")
A28: T | B28: 5 | C28: A | D28: 02 | E28: 4 | F28: =A28&B28&"-"&C28&E28&"-"&D28 | G28: 2021 | H28: =_xlfn.XLOOKUP(G28,'All Associates'!A:A,'All Associates'!B:B) | I28: =_xlfn.XLOOKUP(G28,'All Associates'!A:A,'All Associates'!D:D) | J28: =IF(G28<>"","Allocated","Available")
A29: T | B29: 5 | C29: A | D29: 03 | E29: 4 | F29: =A29&B29&"-"&C29&E29&"-"&D29 | G29: 2045 | H29: =_xlfn.XLOOKUP(G29,'All Associates'!A:A,'All Associates'!B:B) | I29: =_xlfn.XLOOKUP(G29,'All Associates'!A:A,'All Associates'!D:D) | J29: =IF(G29<>"","Allocated","Available")
A30: T | B30: 5 | C30: A | D30: 04 | E30: 4 | F30: =A30&B30&"-"&C30&E30&"-"&D30 | G30: 2014 | H30: =_xlfn.XLOOKUP(G30,'All Associates'!A:A,'All Associates'!B:B) | I30: =_xlfn.XLOOKUP(G30,'All Associates'!A:A,'All Associates'!D:D) | J30: =IF(G30<>"","Allocated","Available")
A31: T | B31: 5 | C31: A | D31: 05 | E31: 4 | F31: =A31&B31&"-"&C31&E31&"-"&D31 | H31: =_xlfn.XLOOKUP(G31,'All Associates'!A:A,'All Associates'!B:B) | I31: =_xlfn.XLOOKUP(G31,'All Associates'!A:A,'All Associates'!D:D) | J31: =IF(G31<>"","Allocated","Available")
A32: T | B32: 5 | C32: A | D32: 06 | E32: 4 | F32: =A32&B32&"-"&C32&E32&"-"&D32 | H32: =_xlfn.XLOOKUP(G32,'All Associates'!A:A,'All Associates'!B:B) | I32: =_xlfn.XLOOKUP(G32,'All Associates'!A:A,'All Associates'!D:D) | J32: =IF(G32<>"","Allocated","Available")
A33: T | B33: 5 | C33: B | D33: 01 | E33: 1 | F33: =A33&B33&"-"&C33&E33&"-"&D33 | G33: 283 | H33: =_xlfn.XLOOKUP(G33,'All Associates'!A:A,'All Associates'!B:B) | I33: =_xlfn.XLOOKUP(G33,'All Associates'!A:A,'All Associates'!D:D) | J33: =IF(G33<>"","Allocated","Available")
A34: T | B34: 5 | C34: B | D34: 02 | E34: 1 | F34: =A34&B34&"-"&C34&E34&"-"&D34 | G34: 954 | H34: =_xlfn.XLOOKUP(G34,'All Associates'!A:A,'All Associates'!B:B) | I34: =_xlfn.XLOOKUP(G34,'All Associates'!A:A,'All Associates'!D:D) | J34: =IF(G34<>"","Allocated","Available")
A35: T | B35: 5 | C35: B | D35: 03 | E35: 1 | F35: =A35&B35&"-"&C35&E35&"-"&D35 | G35: 424 | H35: =_xlfn.XLOOKUP(G35,'All Associates'!A:A,'All Associates'!B:B) | I35: =_xlfn.XLOOKUP(G35,'All Associates'!A:A,'All Associates'!D:D) | J35: =IF(G35<>"","Allocated","Available")
A36: T | B36: 5 | C36: B | D36: 04 | E36: 1 | F36: =A36&B36&"-"&C36&E36&"-"&D36 | G36: 479 | H36: =_xlfn.XLOOKUP(G36,'All Associates'!A:A,'All Associates'!B:B) | I36: =_xlfn.XLOOKUP(G36,'All Associates'!A:A,'All Associates'!D:D) | J36: =IF(G36<>"","Allocated","Available")
A37: T | B37: 5 | C37: B | D37: 05 | E37: 1 | F37: =A37&B37&"-"&C37&E37&"-"&D37 | G37: 1042 | H37: =_xlfn.XLOOKUP(G37,'All Associates'!A:A,'All Associates'!B:B) | I37: =_xlfn.XLOOKUP(G37,'All Associates'!A:A,'All Associates'!D:D) | J37: =IF(G37<>"","Allocated","Available")
A38: T | B38: 5 | C38: B | D38: 01 | E38: 2 | F38: =A38&B38&"-"&C38&E38&"-"&D38 | G38: 1070 | H38: =_xlfn.XLOOKUP(G38,'All Associates'!A:A,'All Associates'!B:B) | I38: =_xlfn.XLOOKUP(G38,'All Associates'!A:A,'All Associates'!D:D) | J38: =IF(G38<>"","Allocated","Available")
A39: T | B39: 5 | C39: B | D39: 02 | E39: 2 | F39: =A39&B39&"-"&C39&E39&"-"&D39 | H39: =_xlfn.XLOOKUP(G39,'All Associates'!A:A,'All Associates'!B:B) | I39: =_xlfn.XLOOKUP(G39,'All Associates'!A:A,'All Associates'!D:D) | J39: =IF(G39<>"","Allocated","Available")
A40: T | B40: 5 | C40: B | D40: 03 | E40: 2 | F40: =A40&B40&"-"&C40&E40&"-"&D40 | G40: 1241 | H40: =_xlfn.XLOOKUP(G40,'All Associates'!A:A,'All Associates'!B:B) | I40: =_xlfn.XLOOKUP(G40,'All Associates'!A:A,'All Associates'!D:D) | J40: =IF(G40<>"","Allocated","Available")
A41: T | B41: 5 | C41: B | D41: 04 | E41: 2 | F41: =A41&B41&"-"&C41&E41&"-"&D41 | H41: =_xlfn.XLOOKUP(G41,'All Associates'!A:A,'All Associates'!B:B) | I41: =_xlfn.XLOOKUP(G41,'All Associates'!A:A,'All Associates'!D:D) | J41: =IF(G41<>"","Allocated","Available")
...

Sheet Tower_6
A1: Building | B1: Floor | C1: Area | D1: Desk Number | E1: Row | F1: Desk number | G1: Associate Staff ID - INPUT | H1: Associate Name | I1: 1st line Supervisor | J1: Desk Status | M1: Floor Plan | O1: Temporar
A2: T | B2: 6 | C2: A | D2: 01 | E2: 1 | F2: =A2&B2&"-"&C2&E2&"-"&D2 | G2: 613 | H2: =_xlfn.XLOOKUP(G2,'All Associates'!A:A,'All Associates'!B:B) | I2: =_xlfn.XLOOKUP(G2,'All Associates'!A:A,'All Associates'!D:D) | J2: =IF(G2<>"","Allocated","Available")
A3: T | B3: 6 | C3: A | D3: 02 | E3: 1 | F3: =A3&B3&"-"&C3&E3&"-"&D3 | G3: 728 | H3: =_xlfn.XLOOKUP(G3,'All Associates'!A:A,'All Associates'!B:B) | I3: =_xlfn.XLOOKUP(G3,'All Associates'!A:A,'All Associates'!D:D) | J3: =IF(G3<>"","Allocated","Available")
A4: T | B4: 6 | C4: A | D4: 03 | E4: 1 | F4: =A4&B4&"-"&C4&E4&"-"&D4 | G4: 1004 | H4: =_xlfn.XLOOKUP(G4,'All Associates'!A:A,'All Associates'!B:B) | I4: =_xlfn.XLOOKUP(G4,'All Associates'!A:A,'All Associates'!D:D) | J4: =IF(G4<>"","Allocated","Available")
A5: T | B5: 6 | C5: A | D5: 04 | E5: 1 | F5: =A5&B5&"-"&C5&E5&"-"&D5 | G5: 908 | H5: =_xlfn.XLOOKUP(G5,'All Associates'!A:A,'All Associates'!B:B) | I5: =_xlfn.XLOOKUP(G5,'All Associates'!A:A,'All Associates'!D:D) | J5: =IF(G5<>"","Allocated","Available")
A6: T | B6: 6 | C6: A | D6: 05 | E6: 1 | F6: =A6&B6&"-"&C6&E6&"-"&D6 | G6: 955 | H6: =_xlfn.XLOOKUP(G6,'All Associates'!A:A,'All Associates'!B:B) | I6: =_xlfn.XLOOKUP(G6,'All Associates'!A:A,'All Associates'!D:D) | J6: =IF(G6<>"","Allocated","Available")
A7: T | B7: 6 | C7: A | D7: 06 | E7: 1 | F7: =A7&B7&"-"&C7&E7&"-"&D7 | G7: 1025 | H7: =_xlfn.XLOOKUP(G7,'All Associates'!A:A,'All Associates'!B:B) | I7: =_xlfn.XLOOKUP(G7,'All Associates'!A:A,'All Associates'!D:D) | J7: =IF(G7<>"","Allocated","Available")
A8: T | B8: 6 | C8: A | D8: 07 | E8: 1 | F8: =A8&B8&"-"&C8&E8&"-"&D8 | G8: 1007 | H8: =_xlfn.XLOOKUP(G8,'All Associates'!A:A,'All Associates'!B:B) | I8: =_xlfn.XLOOKUP(G8,'All Associates'!A:A,'All Associates'!D:D) | J8: =IF(G8<>"","Allocated","Available")
A9: T | B9: 6 | C9: A | D9: 08 | E9: 1 | F9: =A9&B9&"-"&C9&E9&"-"&D9 | G9: 1071 | H9: =_xlfn.XLOOKUP(G9,'All Associates'!A:A,'All Associates'!B:B) | I9: =_xlfn.XLOOKUP(G9,'All Associates'!A:A,'All Associates'!D:D) | J9: =IF(G9<>"","Allocated","Available")
A10: T | B10: 6 | C10: A | D10: 01 | E10: 2 | F10: =A10&B10&"-"&C10&E10&"-"&D10 | G10: 984 | H10: =_xlfn.XLOOKUP(G10,'All Associates'!A:A,'All Associates'!B:B) | I10: =_xlfn.XLOOKUP(G10,'All Associates'!A:A,'All Associates'!D:D) | J10: =IF(G10<>"","Allocated","Available")
A11: T | B11: 6 | C11: A | D11: 02 | E11: 2 | F11: =A11&B11&"-"&C11&E11&"-"&D11 | G11: 509 | H11: =_xlfn.XLOOKUP(G11,'All Associates'!A:A,'All Associates'!B:B) | I11: =_xlfn.XLOOKUP(G11,'All Associates'!A:A,'All Associates'!D:D) | J11: =IF(G11<>"","Allocated","Available")
A12: T | B12: 6 | C12: A | D12: 03 | E12: 2 | F12: =A12&B12&"-"&C12&E12&"-"&D12 | G12: 947 | H12: =_xlfn.XLOOKUP(G12,'All Associates'!A:A,'All Associates'!B:B) | I12: =_xlfn.XLOOKUP(G12,'All Associates'!A:A,'All Associates'!D:D) | J12: =IF(G12<>"","Allocated","Available")
A13: T | B13: 6 | C13: A | D13: 04 | E13: 2 | F13: =A13&B13&"-"&C13&E13&"-"&D13 | G13: 1164 | H13: =_xlfn.XLOOKUP(G13,'All Associates'!A:A,'All Associates'!B:B) | I13: =_xlfn.XLOOKUP(G13,'All Associates'!A:A,'All Associates'!D:D) | J13: =IF(G13<>"","Allocated","Available")
... A25: T | B25: 6 | C25: A | D25: 08 | E25: 3 | F25: =A25&B25&"-"&C25&E25&"-"&D25 | G25: 802 | H25: =_xlfn.XLOOKUP(G25,'All Associates'!A:A,'All Associates'!B:B) | I25: =_xlfn.XLOOKUP(G25,'All Associates'!A:A,'All Associates'!D:D) | J25: =IF(G25<>"","Allocated","Available")
A26: T | B26: 6 | C26: A | D26: 03 | E26: M | F26: =A26&B26&"-"&C26&E26&"-"&D26 | G26: 644 | H26: =_xlfn.XLOOKUP(G26,'All Associates'!A:A,'All Associates'!B:B) | I26: =_xlfn.XLOOKUP(G26,'All Associates'!A:A,'All Associates'!D:D) | J26: =IF(G26<>"","Allocated","Available")
A27: T | B27: 6 | C27: A | D27: 01 | E27: 4 | F27: =A27&B27&"-"&C27&E27&"-"&D27 | G27: 1085 | H27: =_xlfn.XLOOKUP(G27,'All Associates'!A:A,'All Associates'!B:B) | I27: =_xlfn.XLOOKUP(G27,'All Associates'!A:A,'All Associates'!D:D) | J27: =IF(G27<>"","Allocated","Available")
A28: T | B28: 6 | C28: A | D28: 02 | E28: 4 | F28: =A28&B28&"-"&C28&E28&"-"&D28 | G28: 2037 | H28: =_xlfn.XLOOKUP(G28,'All Associates'!A:A,'All Associates'!B:B) | I28: =_xlfn.XLOOKUP(G28,'All Associates'!A:A,'All Associates'!D:D) | J28: =IF(G28<>"","Allocated","Available")
A29: T | B29: 6 | C29: A | D29: 03 | E29: 4 | F29: =A29&B29&"-"&C29&E29&"-"&D29 | G29: 2059 | H29: =_xlfn.XLOOKUP(G29,'All Associates'!A:A,'All Associates'!B:B) | I29: =_xlfn.XLOOKUP(G29,'All Associates'!A:A,'All Associates'!D:D) | J29: =IF(G29<>"","Allocated","Available")
A30: T | B30: 6 | C30: A | D30: 04 | E30: 4 | F30: =A30&B30&"-"&C30&E30&"-"&D30 | G30: 2041 | H30: =_xlfn.XLOOKUP(G30,'All Associates'!A:A,'All Associates'!B:B) | I30: =_xlfn.XLOOKUP(G30,'All Associates'!A:A,'All Associates'!D:D) | J30: =IF(G30<>"","Allocated","Available")
A31: T | B31: 6 | C31: A | D31: 05 | E31: 4 | F31: =A31&B31&"-"&C31&E31&"-"&D31 | G31: 2016 | H31: =_xlfn.XLOOKUP(G31,'All Associates'!A:A,'All Associates'!B:B) | I31: =_xlfn.XLOOKUP(G31,'All Associates'!A:A,'All Associates'!D:D) | J31: =IF(G31<>"","Allocated","Available")
A32: T | B32: 6 | C32: A | D32: 06 | E32: 4 | F32: =A32&B32&"-"&C32&E32&"-"&D32 | G32: 2039 | H32: =_xlfn.XLOOKUP(G32,'All Associates'!A:A,'All Associates'!B:B) | I32: =_xlfn.XLOOKUP(G32,'All Associates'!A:A,'All Associates'!D:D) | J32: =IF(G32<>"","Allocated","Available")
A33: T | B33: 6 | C33: B | D33: 01 | E33: 1 | F33: =A33&B33&"-"&C33&E33&"-"&D33 | G33: 651 | H33: =_xlfn.XLOOKUP(G33,'All Associates'!A:A,'All Associates'!B:B) | I33: =_xlfn.XLOOKUP(G33,'All Associates'!A:A,'All Associates'!D:D) | J33: =IF(G33<>"","Allocated","Available")
A34: T | B34: 6 | C34: B | D34: 02 | E34: 1 | F34: =A34&B34&"-"&C34&E34&"-"&D34 | G34: 536 | H34: =_xlfn.XLOOKUP(G34,'All Associates'!A:A,'All Associates'!B:B) | I34: =_xlfn.XLOOKUP(G34,'All Associates'!A:A,'All Associates'!D:D) | J34: =IF(G34<>"","Allocated","Available")
A35: T | B35: 6 | C35: B | D35: 03 | E35: 1 | F35: =A35&B35&"-"&C35&E35&"-"&D35 | G35: 1020 | H35: =_xlfn.XLOOKUP(G35,'All Associates'!A:A,'All Associates'!B:B) | I35: =_xlfn.XLOOKUP(G35,'All Associates'!A:A,'All Associates'!D:D) | J35: =IF(G35<>"","Allocated","Available")
A36: T | B36: 6 | C36: B | D36: 04 | E36: 1 | F36: =A36&B36&"-"&C36&E36&"-"&D36 | G36: 1102 | H36: =_xlfn.XLOOKUP(G36,'All Associates'!A:A,'All Associates'!B:B) | I36: =_xlfn.XLOOKUP(G36,'All Associates'!A:A,'All Associates'!D:D) | J36: =IF(G36<>"","Allocated","Available")
A37: T | B37: 6 | C37: B | D37: 05 | E37: 1 | F37: =A37&B37&"-"&C37&E37&"-"&D37 | G37: 1011 | H37: =_xlfn.XLOOKUP(G37,'All Associates'!A:A,'All Associates'!B:B) | I37: =_xlfn.XLOOKUP(G37,'All Associates'!A:A,'All Associates'!D:D) | J37: =IF(G37<>"","Allocated","Available")
A38: T | B38: 6 | C38: B | D38: 01 | E38: 2 | F38: =A38&B38&"-"&C38&E38&"-"&D38 | G38: 445 | H38: =_xlfn.XLOOKUP(G38,'All Associates'!A:A,'All Associates'!B:B) | I38: =_xlfn.XLOOKUP(G38,'All Associates'!A:A,'All Associates'!D:D) | J38: =IF(G38<>"","Allocated","Available")
... A41: T | B41: 6 | C41: B | D41: 04 | E41: 2 | F41: =A41&B41&"-"&C41&E41&"-"&D41 | G41: 907 | H41: =_xlfn.XLOOKUP(G41,'All Associates'!A:A,'All Associates'!B:B) | I41: =_xlfn.XLOOKUP(G41,'All Associates'!A:A,'All Associates'!D:D) | J41: =IF(G41<>"","Allocated","Available")
A42: T | B42: 6 | C42: B | D42: 05 | E42: 2 | F42: =A42&B42&"-"&C42&E42&"-"&D42 | H42: =_xlfn.XLOOKUP(G42,'All Associates'!A:A,'All Associates'!B:B) | I42: =_xlfn.XLOOKUP(G42,'All Associates'!A:A,'All Associates'!D:D) | J42: =IF(G42<>"","Allocated","Available")
A43: T | B43: 6 | C43: B | D43: 06 | E43: 2 | F43: =A43&B43&"-"&C43&E43&"-"&D43 | G43: 1006 | H43: =_xlfn.XLOOKUP(G43,'All Associates'!A:A,'All Associates'!B:B) | I43: =_xlfn.XLOOKUP(G43,'All Associates'!A:A,'All Associates'!D:D) | J43: =IF(G43<>"","Allocated","Available")
A44: T | B44: 6 | C44: C | D44: 01 | E44: 1 | F44: =A44&B44&"-"&C44&E44&"-"&D44 | G44: 309 | H44: =_xlfn.XLOOKUP(G44,'All Associates'!A:A,'All Associates'!B:B) | I44: =_xlfn.XLOOKUP(G44,'All Associates'!A:A,'All Associates'!D:D) | J44: =IF(G44<>"","Allocated","Available")
A45: T | B45: 6 | C45: C | D45: 02 | E45: 1 | F45: =A45&B45&"-"&C45&E45&"-"&D45 | G45: 730 | H45: =_xlfn.XLOOKUP(G45,'All Associates'!A:A,'All Associates'!B:B) | I45: =_xlfn.XLOOKUP(G45,'All Associates'!A:A,'All Associates'!D:D) | J45: =IF(G45<>"","Allocated","Available")
A46: T | B46: 6 | C46: C | D46: 03 | E46: 1 | F46: =A46&B46&"-"&C46&E46&"-"&D46 | G46: 718 | H46: =_xlfn.XLOOKUP(G46,'All Associates'!A:A,'All Associates'!B:B) | I46: =_xlfn.XLOOKUP(G46,'All Associates'!A:A,'All Associates'!D:D) | J46: =IF(G46<>"","Allocated","Available")
A47: T | B47: 6 | C47: C | D47: 04 | E47: 1 | F47: =A47&B47&"-"&C47&E47&"-"&D47 | G47: 1063 | H47: =_xlfn.XLOOKUP(G47,'All Associates'!A:A,'All Associates'!B:B) | I47: =_xlfn.XLOOKUP(G47,'All Associates'!A:A,'All Associates'!D:D) | J47: =IF(G47<>"","Allocated","Available")
A48: T | B48: 6 | C48: C | D48: 05 | E48: 1 | F48: =A48&B48&"-"&C48&E48&"-"&D48 | G48: 1218 | H48: =_xlfn.XLOOKUP(G48,'All Associates'!A:A,'All Associates'!B:B) | I48: =_xlfn.XLOOKUP(G48,'All Associates'!A:A,'All Associates'!D:D) | J48: =IF(G48<>"","Allocated","Available")
A49: T | B49: 6 | C49: C | D49: 06 | E49: 1 | F49: =A49&B49&"-"&C49&E49&"-"&D49 | G49: 1221 | H49: =_xlfn.XLOOKUP(G49,'All Associates'!A:A,'All Associates'!B:B) | I49: =_xlfn.XLOOKUP(G49,'All Associates'!A:A,'All Associates'!D:D) | J49: =IF(G49<>"","Allocated","Available")
A50: T | B50: 6 | C50: C | D50: 07 | E50: 1 | F50: =A50&B50&"-"&C50&E50&"-"&D50 | G50: 1223 | H50: =_xlfn.XLOOKUP(G50,'All Associates'!A:A,'All Associates'!B:B) | I50: =_xlfn.XLOOKUP(G50,'All Associates'!A:A,'All Associates'!D:D) | J50: =IF(G50<>"","Allocated","Available")
A51: T | B51: 6 | C51: C | D51: 01 | E51: 2 | F51: =A51&B51&"-"&C51&E51&"-"&D51 | G51: 317 | H51: =_xlfn.XLOOKUP(G51,'All Associates'!A:A,'All Associates'!B:B) | I51: =_xlfn.XLOOKUP(G51,'All Associates'!A:A,'All Associates'!D:D) | J51: =IF(G51<>"","Allocated","Available")
A52: T | B52: 6 | C52: C | D52: 02 | E52: 2 | F52: =A52&B52&"-"&C52&E52&"-"&D52 | G52: 1186 | H52: =_xlfn.XLOOKUP(G52,'All Associates'!A:A,'All Associates'!B:B) | I52: =_xlfn.XLOOKUP(G52,'All Associates'!A:A,'All Associates'!D:D) | J52: =IF(G52<>"","Allocated","Available")
A53: T | B53: 6 | C53: C | D53: 03 | E53: 2 | F53: =A53&B53&"-"&C53&E53&"-"&D53 | G53: 826 | H53: =_xlfn.XLOOKUP(G53,'All Associates'!A:A,'All Associates'!B:B) | I53: =_xlfn.XLOOKUP(G53,'All Associates'!A:A,'All Associates'!D:D) | J53: =IF(G53<>"","Allocated","Available")
...

Sheet Riviera_3
A1: Building | B1: Floor | C1: Area | D1: Desk Number | E1: Row | F1: Desk number | G1: Associate Staff ID - INPUT | H1: Associate Name | I1: 1st line Supervisor | J1: Desk Status | M1: Floor Plan
A2: R | B2: 3 | C2: E | D2: 01 | E2: 1 | F2: =A2&B2&"-"&C2&E2&"-"&D2 | G2: 186 | H2: =_xlfn.XLOOKUP(G2,'All Associates'!A:A,'All Associates'!B:B) | I2: =_xlfn.XLOOKUP(G2,'All Associates'!A:A,'All Associates'!D:D) | J2: =IF(G2<>"","Allocated","Available")
A3: R | B3: 3 | C3: E | D3: 02 | E3: 1 | F3: =A3&B3&"-"&C3&E3&"-"&D3 | H3: =_xlfn.XLOOKUP(G3,'All Associates'!A:A,'All Associates'!B:B) | I3: =_xlfn.XLOOKUP(G3,'All Associates'!A:A,'All Associates'!D:D) | J3: =IF(G3<>"","Allocated","Available")
A4: R | B4: 3 | C4: E | D4: 02 | E4: 1 | F4: =A4&B4&"-"&C4&E4&"-"&D4 | G4: 875 | H4: =_xlfn.XLOOKUP(G4,'All Associates'!A:A,'All Associates'!B:B) | I4: =_xlfn.XLOOKUP(G4,'All Associates'!A:A,'All Associates'!D:D) | J4: =IF(G4<>"","Allocated","Available")
A5: R | B5: 3 | C5: E | D5: 03 | E5: 1 | F5: =A5&B5&"-"&C5&E5&"-"&D5 | G5: 200 | H5: =_xlfn.XLOOKUP(G5,'All Associates'!A:A,'All Associates'!B:B) | I5: =_xlfn.XLOOKUP(G5,'All Associates'!A:A,'All Associates'!D:D) | J5: =IF(G5<>"","Allocated","Available")
A6: R | B6: 3 | C6: E | D6: 04 | E6: 1 | F6: =A6&B6&"-"&C6&E6&"-"&D6 | G6: 1231 | H6: =_xlfn.XLOOKUP(G6,'All Associates'!A:A,'All Associates'!B:B) | I6: =_xlfn.XLOOKUP(G6,'All Associates'!A:A,'All Associates'!D:D) | J6: =IF(G6<>"","Allocated","Available")
A7: R | B7: 3 | C7: E | D7: 05 | E7: 1 | F7: =A7&B7&"-"&C7&E7&"-"&D7 | G7: 2003 | H7: =_xlfn.XLOOKUP(G7,'All Associates'!A:A,'All Associates'!B:B) | I7: =_xlfn.XLOOKUP(G7,'All Associates'!A:A,'All Associates'!D:D) | J7: =IF(G7<>"","Allocated","Available")
A8: R | B8: 3 | C8: E | D8: 01 | E8: 2 | F8: =A8&B8&"-"&C8&E8&"-"&D8 | G8: 829 | H8: =_xlfn.XLOOKUP(G8,'All Associates'!A:A,'All Associates'!B:B) | I8: =_xlfn.XLOOKUP(G8,'All Associates'!A:A,'All Associates'!D:D) | J8: =IF(G8<>"","Allocated","Available")
A9: R | B9: 3 | C9: E | D9: 02 | E9: 2 | F9: =A9&B9&"-"&C9&E9&"-"&D9 | G9: 1109 | H9: =_xlfn.XLOOKUP(G9,'All Associates'!A:A,'All Associates'!B:B) | I9: =_xlfn.XLOOKUP(G9,'All Associates'!A:A,'All Associates'!D:D) | J9: =IF(G9<>"","Allocated","Available")
A10: R | B10: 3 | C10: E | D10: 03 | E10: 2 | F10: =A10&B10&"-"&C10&E10&"-"&D10 | G10: 971 | H10: =_xlfn.XLOOKUP(G10,'All Associates'!A:A,'All Associates'!B:B) | I10: =_xlfn.XLOOKUP(G10,'All Associates'!A:A,'All Associates'!D:D) | J10: =IF(G10<>"","Allocated","Available")
A11: R | B11: 3 | C11: E | D11: 04 | E11: 2 | F11: =A11&B11&"-"&C11&E11&"-"&D11 | G11: 267 | H11: =_xlfn.XLOOKUP(G11,'All Associates'!A:A,'All Associates'!B:B) | I11: =_xlfn.XLOOKUP(G11,'All Associates'!A:A,'All Associates'!D:D) | J11: =IF(G11<>"","Allocated","Available")
A12: R | B12: 3 | C12: E | D12: 05 | E12: 2 | F12: =A12&B12&"-"&C12&E12&"-"&D12 | G12: 690 | H12: =_xlfn.XLOOKUP(G12,'All Associates'!A:A,'All Associates'!B:B) | I12: =_xlfn.XLOOKUP(G12,'All Associates'!A:A,'All Associates'!D:D) | J12: =IF(G12<>"","Allocated","Available")
A13: R | B13: 3 | C13: E | D13: 06 | E13: 2 | F13: =A13&B13&"-"&C13&E13&"-"&D13 | G13: 2056 | H13: =_xlfn.XLOOKUP(G13,'All Associates'!A:A,'All Associates'!B:B) | I13: =_xlfn.XLOOKUP(G13,'All Associates'!A:A,'All Associates'!D:D) | J13: =IF(G13<>"","Allocated","Available")
A14: R | B14: 3 | C14: E | D14: 01 | E14: 3 | F14: =A14&B14&"-"&C14&E14&"-"&D14 | G14: 576 | H14: =_xlfn.XLOOKUP(G14,'All Associates'!A:A,'All Associates'!B:B) | I14: =_xlfn.XLOOKUP(G14,'All Associates'!A:A,'All Associates'!D:D) | J14: =IF(G14<>"","Allocated","Available")
A15: R | B15: 3 | C15: E | D15: 02 | E15: 3 | F15: =A15&B15&"-"&C15&E15&"-"&D15 | G15: 196 | H15: =_xlfn.XLOOKUP(G15,'All Associates'!A:A,'All Associates'!B:B) | I15: =_xlfn.XLOOKUP(G15,'All Associates'!A:A,'All Associates'!D:D) | J15: =IF(G15<>"","Allocated","Available")
... A19: R | B19: 3 | C19: E | D19: 06 | E19: 3 | F19: =A19&B19&"-"&C19&E19&"-"&D19 | G19: 2052 | H19: =_xlfn.XLOOKUP(G19,'All Associates'!A:A,'All Associates'!B:B) | I19: =_xlfn.XLOOKUP(G19,'All Associates'!A:A,'All Associates'!D:D) | J19: =IF(G19<>"","Allocated","Available")
A20: R | B20: 3 | C20: E | D20: 07 | E20: 3 | F20: =A20&B20&"-"&C20&E20&"-"&D20 | H20: =_xlfn.XLOOKUP(G20,'All Associates'!A:A,'All Associates'!B:B) | I20: =_xlfn.XLOOKUP(G20,'All Associates'!A:A,'All Associates'!D:D) | J20: =IF(G20<>"","Allocated","Available")
A21: R | B21: 3 | C21: E | D21: 08 | E21: 3 | F21: =A21&B21&"-"&C21&E21&"-"&D21 | H21: =_xlfn.XLOOKUP(G21,'All Associates'!A:A,'All Associates'!B:B) | I21: =_xlfn.XLOOKUP(G21,'All Associates'!A:A,'All Associates'!D:D) | J21: =IF(G21<>"","Allocated","Available")
A22: R | B22: 3 | C22: E | D22: 01 | E22: 4 | F22: =A22&B22&"-"&C22&E22&"-"&D22 | G22: 663 | H22: =_xlfn.XLOOKUP(G22,'All Associates'!A:A,'All Associates'!B:B) | I22: =_xlfn.XLOOKUP(G22,'All Associates'!A:A,'All Associates'!D:D) | J22: =IF(G22<>"","Allocated","Available")
A23: R | B23: 3 | C23: E | D23: 02 | E23: 4 | F23: =A23&B23&"-"&C23&E23&"-"&D23 | G23: 675 | H23: =_xlfn.XLOOKUP(G23,'All Associates'!A:A,'All Associates'!B:B) | I23: =_xlfn.XLOOKUP(G23,'All Associates'!A:A,'All Associates'!D:D) | J23: =IF(G23<>"","Allocated","Available")
A24: R | B24: 3 | C24: E | D24: 03 | E24: 4 | F24: =A24&B24&"-"&C24&E24&"-"&D24 | G24: 610 | H24: =_xlfn.XLOOKUP(G24,'All Associates'!A:A,'All Associates'!B:B) | I24: =_xlfn.XLOOKUP(G24,'All Associates'!A:A,'All Associates'!D:D) | J24: =IF(G24<>"","Allocated","Available")
A25: R | B25: 3 | C25: E | D25: 04 | E25: 4 | F25: =A25&B25&"-"&C25&E25&"-"&D25 | G25: 809 | H25: =_xlfn.XLOOKUP(G25,'All Associates'!A:A,'All Associates'!B:B) | I25: =_xlfn.XLOOKUP(G25,'All Associates'!A:A,'All Associates'!D:D) | J25: =IF(G25<>"","Allocated","Available")
A26: R | B26: 3 | C26: E | D26: 05 | E26: 4 | F26: =A26&B26&"-"&C26&E26&"-"&D26 | G26: 960 | H26: =_xlfn.XLOOKUP(G26,'All Associates'!A:A,'All Associates'!B:B) | I26: =_xlfn.XLOOKUP(G26,'All Associates'!A:A,'All Associates'!D:D) | J26: =IF(G26<>"","Allocated","Available")
A27: R | B27: 3 | C27: E | D27: 06 | E27: 4 | F27: =A27&B27&"-"&C27&E27&"-"&D27 | G27: 933 | H27: =_xlfn.XLOOKUP(G27,'All Associates'!A:A,'All Associates'!B:B) | I27: =_xlfn.XLOOKUP(G27,'All Associates'!A:A,'All Associates'!D:D) | J27: =IF(G27<>"","Allocated","Available")
A28: R | B28: 3 | C28: F | D28: 01 | E28: 1 | F28: =A28&B28&"-"&C28&E28&"-"&D28 | G28: HW | J28: HW
A29: R | B29: 3 | C29: F | D29: 02 | E29: 1 | F29: =A29&B29&"-"&C29&E29&"-"&D29 | G29: HW | J29: HW
A30: R | B30: 3 | C30: F | D30: 03 | E30: 1 | F30: =A30&B30&"-"&C30&E30&"-"&D30 | G30: HW | J30: HW
A31: R | B31: 3 | C31: F | D31: 01 | E31: 2 | F31: =A31&B31&"-"&C31&E31&"-"&D31 | G31: HW | J31: HW
